2021-01-11 16:56:10,011	WARNING worker.py:1091 -- The dashboard on node gardner.local failed with the following error:
Traceback (most recent call last):
  File "/home/pminervi/anaconda3/envs/gpu/lib/python3.6/site-packages/ray/dashboard/dashboard.py", line 963, in <module>
    dashboard.run()
  File "/home/pminervi/anaconda3/envs/gpu/lib/python3.6/site-packages/ray/dashboard/dashboard.py", line 577, in run
    aiohttp.web.run_app(self.app, host=self.host, port=self.port)
  File "/home/pminervi/anaconda3/envs/gpu/lib/python3.6/site-packages/aiohttp/web.py", line 508, in run_app
    loop.run_until_complete(main_task)
  File "/home/pminervi/anaconda3/envs/gpu/lib/python3.6/asyncio/base_events.py", line 484, in run_until_complete
    return future.result()
  File "/home/pminervi/anaconda3/envs/gpu/lib/python3.6/site-packages/aiohttp/web.py", line 411, in _run_app
    await site.start()
  File "/home/pminervi/anaconda3/envs/gpu/lib/python3.6/site-packages/aiohttp/web_runner.py", line 128, in start
    reuse_port=self._reuse_port,
  File "/home/pminervi/anaconda3/envs/gpu/lib/python3.6/asyncio/base_events.py", line 1082, in create_server
    sock.listen(backlog)
OSError: [Errno 98] Address already in use

2021-01-11 17:03:38,915	WARNING import_thread.py:132 -- The remote function 'maprop.blackbox.dijkstra.solver' has been exported 100 times. It's possible that this warning is accidental, but this may indicate that the same remote function is being defined repeatedly from within many tasks and exported to all of the workers. This can be a performance issue and can be resolved by defining the remote function on the driver instead. See https://github.com/ray-project/ray/issues/6240 for more discussion.
